Workbook

Sheet Ficha
B1: FICHA DEL PROYECTO
B2: Llena solo las celdas verdes. * = obligatorio. Un archivo por proyecto.
B3: Dato | C3: Valor | D3: Indicación
B4: Código de obra * | C4: OP-26-020 | D4: Obligatorio y único por obra · Ej.: OP-26-014
B5: Cliente * | C5: Tambo | D5: Elige de la lista
B6: Tienda / sede * | C6: Samame Surco | D6: Ej.: Lince
B7: Departamento * | C7: Lima | D7: Elige de la lista
B8: Jefe de proyecto * | C8: Carlos G. | D8: Elige de la lista (o escribe uno nuevo)
B9: Coordinador * | C9: Abel Narvaez | D9: Elige de la lista (o escribe uno nuevo)
B10: Estado * | C10: En ejecución | D10: Próximo proyecto, En ejecución, Post venta, Culminado, Suspendida o Cancelada
B11: Fecha de inicio * | C11: 46288 | D11: dd/mm/aaaa · si la dejas vacía se toma de las partidas
B12: Fecha de fin * | C12: 46321 | D12: dd/mm/aaaa · máximo 10 semanas desde el inicio
B13: % avance general (0 a 100) | D13: Solo si NO llenas la hoja Partidas
B14: Comentario | D14: Opcional · se ve en la pantalla en vivo
B15: Encargado de actualizar | C15: Carlos G. | D15: Nombre de quien actualiza este archivo
B16: Fecha de actualización | C16: 46314 | D16: dd/mm/aaaa
B18: Post venta (llenar al entregar la obra)
B19: Fecha de entrega real | D19: dd/mm/aaaa · día en que se entregó la obra (inicia la post venta)
B20: Fecha de cierre de post venta | D20: dd/mm/aaaa · vacía mientras siga abierta (la post venta no tiene plazo fijo)
B21: Observaciones de post venta | D21: Pendientes o levantamientos
B24: Resumen (cálculo automático)
B25: Plazo según partidas | C25: =IF(COUNT(Partidas!E6:E305)=0,"",TEXT(MIN(Partidas!E6:E305),"dd/mm/yyyy")&" – "&TEXT(MAX(Partidas!F6:F305),"dd/mm/yyyy")) -> 23/09/2026 – 26/10/2026
B26: Avance real calculado (%) | C26: =IF(SUM(Partidas!BC6:BC305)=0,IF(C13="","",C13),ROUNDDOWN(ROUND(SUMPRODUCT(Partidas!BC6:BC305,Partidas!AI6:AI305)/SUM(Partidas!BC6:BC305),6),0)) -> 79
B27: Programado al cierre de la semana anterior (%) | C27: =IF(OR(C10="Post venta",C10="Culminado"),100,IF(OR(C10="Suspendida",C10="Cancelada"),C26,IF(Reprogramaciones!$X$15="","",ROUNDDOWN(ROUND(Reprogramaciones!$X$15,6),0)))) -> 79
B28: Situación de ejecución | C28: =IF(C10="Suspendida","Suspendida",IF(C10="Cancelada","Cancelada",IF(AND(C10="En ejecución",SUMPRODUCT((Reprogramaciones!$H$5:$H$14="OK")*(Reprogramaciones!$C$5:$C$14<=TODAY())*(Reprogramaciones!$C$5:$C$14+Reprogramaciones!$D$5:$D$14>TODAY()))>0),"En pausa",IF(OR(C10="Post venta",C10="Culminado"),"Entregada",IF(OR(C26="",C27=""),"",IF(C26>=100,"Por entregar",IF(AND(N(Partidas!$J$2)>TODAY(),N(Reprogramaciones!$V$15)=0),"Por iniciar",IF(Reprogramaciones!$V$15+0.5<Reprogramaciones!$X$15,"Retrasada",IF(Reprogramaciones!$Y$15,"En riesgo",IF(Reprogramaciones!$V$15+0.5<Reprogramaciones!$W$15,IF(Reprogramaciones!$K$15>0,"Al día · Sem "&Reprogramaciones!$K$15&" en curso","Al día · en curso"),"A tiempo")))))))))) -> Al día · Sem 5 en curso
B29: Inicio de post venta | C29: =IF(OR(C10="Post venta",C10="Culminado"),IF(C19<>"",C19,IF(C12<>"",C12,"")),"") | D29: =IF(C29="","",IF(C20<>"",C20,TODAY())-C29&" días en post venta")
B30: Situación de post venta | C30: =IF(C29="","",IF(C20<>"","Cerrada en "&(C20-C29)&" días","En curso · "&(TODAY()-C29)&" días"))
B31: Revisión de la ficha | C31: =IF(COUNTA(C5:C10)=0,"Sin llenar",IF(C4="","Falta el código de obra",IF(C5="","Falta el cliente",IF(C6="","Falta la tienda",IF(C7="","Falta el departamento",IF(C8="","Falta el jefe",IF(C9="","Falta el coordinador",IF(C10="","Falta el estado",IF(AND(C11="",COUNT(Partidas!E6:E305)=0),"Falta la fecha de inicio",IF(AND(C12="",COUNT(Partidas!F6:F305)=0),"Falta la fecha de fin",IF(AND(C11<>"",C12<>"",C12<C11),"El fin es anterior al inicio",IF(AND(C10="Post venta",C19=""),"Falta la fecha de entrega real",IF(AND(C19<>"",C20<>"",C20<C19),"El cierre es anterior a la entrega",IF(AND(C11<>"",C12<>"",C12-C11>69),"La obra supera 10 semanas",IF(Reprogramaciones!$E$23<>"OK","Revisar Reprogramaciones",IF(AND(OR(C10="Post venta",C10="Culminado"),ISNUMBER(C26),N(C26)<100),"Entregada sin el 100% de avance",IF(AND(C19<>"",OR(C10="En ejecución",C10="Próximo proyecto")),"Tiene fecha de entrega: cambia el estado a Post venta",IF(AND(ISNUMBER(C16),C16>TODAY()),"La fecha de actualización es posterior a hoy",IF(COUNTIF(Partidas!$AL$6:$AL$305,"Avance después del fin*")>0,"Hay avance después del fin de la obra: registra una reprogramación por atraso (causa Interno)","OK"))))))))))))))))))) -> OK
B32: Adicionales | C32: =IF(COUNTIFS(Partidas!CZ6:CZ305,"Adicional",Partidas!BC6:BC305,">0")=0,"Sin adicionales",COUNTIFS(Partidas!CZ6:CZ305,"Adicional",Partidas!BC6:BC305,">0")&" subpartida"&IF(COUNTIFS(Partidas!CZ6:CZ305,"Adicional",Partidas!BC6:BC305,">0")=1,"","s")&" · "&ROUND(SUMPRODUCT(--(Partidas!CZ6:CZ305="Adicional"),Partidas!BC6:BC305,Partidas!AI6:AI305)/SUMPRODUCT(--(Partidas!CZ6:CZ305="Adicional"),Partidas!BC6:BC305),0)&"% de avance · "&ROUND(SUMPRODUCT(--(Partidas!CZ6:CZ305="Adicional"),Partidas!BC6:BC305)/SUM(Partidas!BC6:BC305)*100,0)&"% del trabajo") -> Sin adicionales
B33: Reprogramación | C33: =Reprogramaciones!$E$22 -> Sin reprogramación | D33: Se registra en la hoja Reprogramaciones
B35: Equipo del proyecto
B36: Residente de obra | C36: Melany Antuanett Huarhua Lagos | D36: Elige de la lista (o escribe uno nuevo)
B37: Responsable de presupuesto | C37: Lucía Ramos | D37: Elige de la lista (o escribe uno nuevo)
B38: Responsable de procura | C38: Rosa Quispe | D38: Elige de la lista (o escribe uno nuevo)

Sheet Partidas
A1: PARTIDAS, METAS Y AVANCE SEMANAL | AM1: Azul = programado sin reporte · Verde = al día · Ámbar = semana en curso, aún bajo la meta · Rojo = semana cerrada sin cumplir la meta · «Pend.» = venció sin llegar a 100% · Lila = semana en pausa por reprogramación | DC1: =Reprogramaciones!K$8 -> 46286 | DD1: =Reprogramaciones!L$8 -> 46293 | DE1: =Reprogramaciones!M$8 -> 46300 | DF1: =Reprogramaciones!N$8 -> 46307 | DG1: =Reprogramaciones!O$8 -> 46314 | DH1: =Reprogramaciones!P$8 -> 46321 | DI1: =Reprogramaciones!Q$8 -> 46328 | DJ1: =Reprogramaciones!R$8 -> 46335 | ... DR1: =Reprogramaciones!Z$8 -> 46391 | DS1: =Reprogramaciones!$K$15 -> 5
A2: =IF(Ficha!C5="","(llena la ficha)",Ficha!C4&" "&Ficha!C5&" "&Ficha!C6) -> OP-26-020 Tambo Samame Surco | G2: Inicio de la obra: | J2: =IF(Ficha!C11<>"",Ficha!C11,IF(COUNT(E6:E305)=0,"",MIN(E6:E305))) -> 46288 | M2: Semana en curso: | P2: =IF($J$2="","",Reprogramaciones!$K$15) -> 5 | Q2: =IF(COUNTIF($AL$6:$AL$305,"Avance después del fin*")=0,"","⚠ Hay avance registrado después del fin de la obra ("&TEXT(Reprogramaciones!$E$21,"dd/mm/yyyy")&"). Registra una reprogramación por atraso en la hoja Reprogramaciones (causa: Interno).") | AM2: Reprogramación: | AO2: =Reprogramaciones!$E$22 -> Sin reprogramación | DC2: =Reprogramaciones!K$9 -> 46292 | DD2: =Reprogramaciones!L$9 -> 46299 | DE2: =Reprogramaciones!M$9 -> 46306 | DF2: =Reprogramaciones!N$9 -> 46313 | DG2: =Reprogramaciones!O$9 -> 46320 | DH2: =Reprogramaciones!P$9 -> 46327 | DI2: =Reprogramaciones!Q$9 -> 46334 | DJ2: =Reprogramaciones!R$9 -> 46341 | ... DR2: =Reprogramaciones!Z$9 -> 46397 | DS2: =Reprogramaciones!$U$15 -> 6
A3: Beige = jefe / presupuesto: partidas, fechas y META de cada semana (% de la subpartida que se espera lograr; viene calculada con los días laborables, de lunes a sábado, y se puede reemplazar; debe sumar 100). Tipo: Adicional para trabajos fuera del contrato. Verde = coordinador: lo AVANZADO en cada semana (lunes a domingo; se reporta el sábado). Gris = automático. Las semanas son de lunes a domingo y la Sem 1 es la semana en que empieza la obra. Si la obra se reprograma, NO se cambian estas fechas: se registra en la hoja Reprogramaciones y el plan se corre solo. | G3: META: % ESPERADO EN LA SEMANA | Q3: AVANCE REAL DE LA SEMANA (%) | AM3: CRONOGRAMA: PACTADO / REAL ACUMULADO | DC3: =Reprogramaciones!K$12 -> 0 | DD3: =Reprogramaciones!L$12 -> 0 | DE3: =Reprogramaciones!M$12 -> 0 | DF3: =Reprogramaciones!N$12 -> 0 | DG3: =Reprogramaciones!O$12 -> 0 | DH3: =Reprogramaciones!P$12 -> 0 | DI3: =Reprogramaciones!Q$12 -> 0 | DJ3: =Reprogramaciones!R$12 -> 0 | ... DR3: =Reprogramaciones!Z$12 -> 0 | DS3: =Reprogramaciones!$E$21 -> 46321
G4: =IF($J$2="","",TEXT(Reprogramaciones!K$8,"dd/mm")&CHAR(10)&TEXT(Reprogramaciones!K$9,"dd/mm")) -> 21/09 27/09 | H4: =IF($J$2="","",TEXT(Reprogramaciones!L$8,"dd/mm")&CHAR(10)&TEXT(Reprogramaciones!L$9,"dd/mm")) -> 28/09 04/10 | I4: =IF($J$2="","",TEXT(Reprogramaciones!M$8,"dd/mm")&CHAR(10)&TEXT(Reprogramaciones!M$9,"dd/mm")) -> 05/10 11/10 | J4: =IF($J$2="","",TEXT(Reprogramaciones!N$8,"dd/mm")&CHAR(10)&TEXT(Reprogramaciones!N$9,"dd/mm")) -> 12/10 18/10 | K4: =IF($J$2="","",TEXT(Reprogramaciones!O$8,"dd/mm")&CHAR(10)&TEXT(Reprogramaciones!O$9,"dd/mm")) -> 19/10 25/10 | L4: =IF($J$2="","",TEXT(Reprogramaciones!P$8,"dd/mm")&CHAR(10)&TEXT(Reprogramaciones!P$9,"dd/mm")) -> 26/10 01/11 | M4: =IF($J$2="","",TEXT(Reprogramaciones!Q$8,"dd/mm")&CHAR(10)&TEXT(Reprogramaciones!Q$9,"dd/mm")) -> 02/11 08/11 | N4: =IF($J$2="","",TEXT(Reprogramaciones!R$8,"dd/mm")&CHAR(10)&TEXT(Reprogramaciones!R$9,"dd/mm")) -> 09/11 15/11 | ... P4: =IF($J$2="","",TEXT(Reprogramaciones!T$8,"dd/mm")&CHAR(10)&TEXT(Reprogramaciones!T$9,"dd/mm")) -> 23/11 29/11 | Q4: =IF(OR($J$2="",AND(1>10,1>Reprogramaciones!$U$15)),"",TEXT(Reprogramaciones!K$8,"dd/mm")&CHAR(10)&TEXT(Reprogramaciones!K$9,"dd/mm")) -> 21/09 27/09 | R4: =IF(OR($J$2="",AND(2>10,2>Reprogramaciones!$U$15)),"",TEXT(Reprogramaciones!L$8,"dd/mm")&CHAR(10)&TEXT(Reprogramaciones!L$9,"dd/mm")) -> 28/09 04/10 | S4: =IF(OR($J$2="",AND(3>10,3>Reprogramaciones!$U$15)),"",TEXT(Reprogramaciones!M$8,"dd/mm")&CHAR(10)&TEXT(Reprogramaciones!M$9,"dd/mm")) -> 05/10 11/10 | T4: =IF(OR($J$2="",AND(4>10,4>Reprogramaciones!$U$15)),"",TEXT(Reprogramaciones!N$8,"dd/mm")&CHAR(10)&TEXT(Reprogramaciones!N$9,"dd/mm")) -> 12/10 18/10 | U4: =IF(OR($J$2="",AND(5>10,5>Reprogramaciones!$U$15)),"",TEXT(Reprogramaciones!O$8,"dd/mm")&CHAR(10)&TEXT(Reprogramaciones!O$9,"dd/mm")) -> 19/10 25/10 | V4: =IF(OR($J$2="",AND(6>10,6>Reprogramaciones!$U$15)),"",TEXT(Reprogramaciones!P$8,"dd/mm")&CHAR(10)&TEXT(Reprogramaciones!P$9,"dd/mm")) -> 26/10 01/11 | W4: =IF(OR($J$2="",AND(7>10,7>Reprogramaciones!$U$15)),"",TEXT(Reprogramaciones!Q$8,"dd/mm")&CHAR(10)&TEXT(Reprogramaciones!Q$9,"dd/mm")) -> 02/11 08/11 | X4: =IF(OR($J$2="",AND(8>10,8>Reprogramaciones!$U$15)),"",TEXT(Reprogramaciones!R$8,"dd/mm")&CHAR(10)&TEXT(Reprogramaciones!R$9,"dd/mm")) -> 09/11 15/11 | Y4: =IF(OR($J$2="",AND(9>10,9>Reprogramaciones!$U$15)),"",TEXT(Reprogramaciones!S$8,"dd/mm")&CHAR(10)&TEXT(Reprogramaciones!S$9,"dd/mm")) -> 16/11 22/11 | Z4: =IF(OR($J$2="",AND(10>10,10>Reprogramaciones!$U$15)),"",TEXT(Reprogramaciones!T$8,"dd/mm")&CHAR(10)&TEXT(Reprogramaciones!T$9,"dd/mm")) -> 23/11 29/11 | AA4: =IF(OR($J$2="",AND(11>10,11>Reprogramaciones!$U$15)),"",TEXT(Reprogramaciones!U$8,"dd/mm")&CHAR(10)&TEXT(Reprogramaciones!U$9,"dd/mm")) | AB4: =IF(OR($J$2="",AND(12>10,12>Reprogramaciones!$U$15)),"",TEXT(Reprogramaciones!V$8,"dd/mm")&CHAR(10)&TEXT(Reprogramaciones!V$9,"dd/mm")) | AC4: =IF(OR($J$2="",AND(13>10,13>Reprogramaciones!$U$15)),"",TEXT(Reprogramaciones!W$8,"dd/mm")&CHAR(10)&TEXT(Reprogramaciones!W$9,"dd/mm")) | AD4: =IF(OR($J$2="",AND(14>10,14>Reprogramaciones!$U$15)),"",TEXT(Reprogramaciones!X$8,"dd/mm")&CHAR(10)&TEXT(Reprogramaciones!X$9,"dd/mm")) | AE4: =IF(OR($J$2="",AND(15>10,15>Reprogramaciones!$U$15)),"",TEXT(Reprogramaciones!Y$8,"dd/mm")&CHAR(10)&TEXT(Reprogramaciones!Y$9,"dd/mm")) | AF4: =IF(OR($J$2="",AND(16>10,16>Reprogramaciones!$U$15)),"",TEXT(Reprogramaciones!Z$8,"dd/mm")&CHAR(10)&TEXT(Reprogramaciones!Z$9,"dd/mm")) | AM4: =IF(OR($J$2="",1>MAX(1,Reprogramaciones!$U$15)),"",TEXT(Reprogramaciones!K$8,"dd/mm")&CHAR(10)&TEXT(Reprogramaciones!K$9,"dd/mm")) -> 21/09 27/09 | AN4: =IF(OR($J$2="",2>MAX(1,Reprogramaciones!$U$15)),"",TEXT(Reprogramaciones!L$8,"dd/mm")&CHAR(10)&TEXT(Reprogramaciones!L$9,"dd/mm")) -> 28/09 04/10 | AO4: =IF(OR($J$2="",3>MAX(1,Reprogramaciones!$U$15)),"",TEXT(Reprogramaciones!M$8,"dd/mm")&CHAR(10)&TEXT(Reprogramaciones!M$9,"dd/mm")) -> 05/10 11/10 | AP4: =IF(OR($J$2="",4>MAX(1,Reprogramaciones!$U$15)),"",TEXT(Reprogramaciones!N$8,"dd/mm")&CHAR(10)&TEXT(Reprogramaciones!N$9,"dd/mm")) -> 12/10 18/10 | AQ4: =IF(OR($J$2="",5>MAX(1,Reprogramaciones!$U$15)),"",TEXT(Reprogramaciones!O$8,"dd/mm")&CHAR(10)&TEXT(Reprogramaciones!O$9,"dd/mm")) -> 19/10 25/10 | AR4: =IF(OR($J$2="",6>MAX(1,Reprogramaciones!$U$15)),"",TEXT(Reprogramaciones!P$8,"dd/mm")&CHAR(10)&TEXT(Reprogramaciones!P$9,"dd/mm")) -> 26/10 01/11 | AS4: =IF(OR($J$2="",7>MAX(1,Reprogramaciones!$U$15)),"",TEXT(Reprogramaciones!Q$8,"dd/mm")&CHAR(10)&TEXT(Reprogramaciones!Q$9,"dd/mm")) | AT4: =IF(OR($J$2="",8>MAX(1,Reprogramaciones!$U$15)),"",TEXT(Reprogramaciones!R$8,"dd/mm")&CHAR(10)&TEXT(Reprogramaciones!R$9,"dd/mm")) | AU4: =IF(OR($J$2="",9>MAX(1,Reprogramaciones!$U$15)),"",TEXT(Reprogramaciones!S$8,"dd/mm")&CHAR(10)&TEXT(Reprogramaciones!S$9,"dd/mm")) | AV4: =IF(OR($J$2="",10>MAX(1,Reprogramaciones!$U$15)),"",TEXT(Reprogramaciones!T$8,"dd/mm")&CHAR(10)&TEXT(Reprogramaciones!T$9,"dd/mm")) | AW4: =IF(OR($J$2="",11>MAX(1,Reprogramaciones!$U$15)),"",TEXT(Reprogramaciones!U$8,"dd/mm")&CHAR(10)&TEXT(Reprogramaciones!U$9,"dd/mm")) | AX4: =IF(OR($J$2="",12>MAX(1,Reprogramaciones!$U$15)),"",TEXT(Reprogramaciones!V$8,"dd/mm")&CHAR(10)&TEXT(Reprogramaciones!V$9,"dd/mm")) | AY4: =IF(OR($J$2="",13>MAX(1,Reprogramaciones!$U$15)),"",TEXT(Reprogramaciones!W$8,"dd/mm")&CHAR(10)&TEXT(Reprogramaciones!W$9,"dd/mm")) | AZ4: =IF(OR($J$2="",14>MAX(1,Reprogramaciones!$U$15)),"",TEXT(Reprogramaciones!X$8,"dd/mm")&CHAR(10)&TEXT(Reprogramaciones!X$9,"dd/mm")) | BA4: =IF(OR($J$2="",15>MAX(1,Reprogramaciones!$U$15)),"",TEXT(Reprogramaciones!Y$8,"dd/mm")&CHAR(10)&TEXT(Reprogramaciones!Y$9,"dd/mm")) | BB4: =IF(OR($J$2="",16>MAX(1,Reprogramaciones!$U$15)),"",TEXT(Reprogramaciones!Z$8,"dd/mm")&CHAR(10)&TEXT(Reprogramaciones!Z$9,"dd/mm"))
A5: Ítem | B5: Partida | C5: Subpartida | D5: Tipo | E5: Inicio prog. | F5: Fin prog. | G5: Meta sem 1 | H5: Meta sem 2 | I5: Meta sem 3 | J5: Meta sem 4 | K5: Meta sem 5 | L5: Meta sem 6 | M5: Meta sem 7 | N5: Meta sem 8 | O5: Meta sem 9 | P5: Meta sem 10 | Q5: Avance sem 1 | R5: Avance sem 2 | S5: Avance sem 3 | T5: Avance sem 4 | U5: Avance sem 5 | V5: Avance sem 6 | W5: Avance sem 7 | X5: Avance sem 8 | Y5: Avance sem 9 | Z5: Avance sem 10 | AA5: =IF(OR($J$2="",11>Reprogramaciones!$U$15),"","Avance sem 11") | AB5: =IF(OR($J$2="",12>Reprogramaciones!$U$15),"","Avance sem 12") | AC5: =IF(OR($J$2="",13>Reprogramaciones!$U$15),"","Avance sem 13") | AD5: =IF(OR($J$2="",14>Reprogramaciones!$U$15),"","Avance sem 14") | AE5: =IF(OR($J$2="",15>Reprogramaciones!$U$15),"","Avance sem 15") | AF5: =IF(OR($J$2="",16>Reprogramaciones!$U$15),"","Avance sem 16") | AG5: Días lab. | AH5: % programado (cierre de la semana anterior) | AI5: % real acumulado | AJ5: Desviación (pp) | AK5: Situación | AL5: Revisión | AM5: =IF(OR($J$2="",1>MAX(1,Reprogramaciones!$U$15)),"","Sem 1") -> Sem 1 | AN5: =IF(OR($J$2="",2>MAX(1,Reprogramaciones!$U$15)),"","Sem 2") -> Sem 2 | AO5: =IF(OR($J$2="",3>MAX(1,Reprogramaciones!$U$15)),"","Sem 3") -> Sem 3 | AP5: =IF(OR($J$2="",4>MAX(1,Reprogramaciones!$U$15)),"","Sem 4") -> Sem 4 | AQ5: =IF(OR($J$2="",5>MAX(1,Reprogramaciones!$U$15)),"","Sem 5") -> Sem 5 | AR5: =IF(OR($J$2="",6>MAX(1,Reprogramaciones!$U$15)),"","Sem 6") -> Sem 6 | AS5: =IF(OR($J$2="",7>MAX(1,Reprogramaciones!$U$15)),"","Sem 7") | AT5: =IF(OR($J$2="",8>MAX(1,Reprogramaciones!$U$15)),"","Sem 8") | AU5: =IF(OR($J$2="",9>MAX(1,Reprogramaciones!$U$15)),"","Sem 9") | AV5: =IF(OR($J$2="",10>MAX(1,Reprogramaciones!$U$15)),"","Sem 10") | AW5: =IF(OR($J$2="",11>MAX(1,Reprogramaciones!$U$15)),"","Sem 11") | AX5: =IF(OR($J$2="",12>MAX(1,Reprogramaciones!$U$15)),"","Sem 12") | AY5: =IF(OR($J$2="",13>MAX(1,Reprogramaciones!$U$15)),"","Sem 13") | AZ5: =IF(OR($J$2="",14>MAX(1,Reprogramaciones!$U$15)),"","Sem 14") | BA5: =IF(OR($J$2="",15>MAX(1,Reprogramaciones!$U$15)),"","Sem 15") | BB5: =IF(OR($J$2="",16>MAX(1,Reprogramaciones!$U$15)),"","Sem 16") | BC5: Peso | BD5: Pactado original acum. sem 1 | BE5: Pactado original acum. sem 2 | BF5: Pactado original acum. sem 3 | BG5: Pactado original acum. sem 4 | BH5: Pactado original acum. sem 5 | BI5: Pactado original acum. sem 6 | BJ5: Pactado original acum. sem 7 | BK5: Pactado original acum. sem 8 | BL5: Pactado original acum. sem 9 | BM5: Pactado original acum. sem 10 | BN5: Pactado original acum. sem 11 | BO5: Pactado original acum. sem 12 | BP5: Pactado original acum. sem 13 | BQ5: Pactado original acum. sem 14 | BR5: Pactado original acum. sem 15 | BS5: Pactado original acum. sem 16 | BT5: Pactado control acum. sem 1 | BU5: Pactado control acum. sem 2 | BV5: Pactado control acum. sem 3 | BW5: Pactado control acum. sem 4 | BX5: Pactado control acum. sem 5 | BY5: Pactado control acum. sem 6 | BZ5: Pactado control acum. sem 7 | CA5: Pactado control acum. sem 8 | CB5: Pactado control acum. sem 9 | CC5: Pactado control acum. sem 10 | CD5: Pactado control acum. sem 11 | CE5: Pactado control acum. sem 12 | CF5: Pactado control acum. sem 13 | CG5: Pactado control acum. sem 14 | CH5: Pactado control acum. sem 15 | CI5: Pactado control acum. sem 16 | CJ5: Real acum. sem 1 | CK5: Real acum. sem 2 | CL5: Real acum. sem 3 | CM5: Real acum. sem 4 | CN5: Real acum. sem 5 | CO5: Real acum. sem 6 | CP5: Real acum. sem 7 | CQ5: Real acum. sem 8 | CR5: Real acum. sem 9 | CS5: Real acum. sem 10 | CT5: Real acum. sem 11 | CU5: Real acum. sem 12 | CV5: Real acum. sem 13 | CW5: Real acum. sem 14 | CX5: Real acum. sem 15 | CY5: Real acum. sem 16 | CZ5: Tipo efectivo | DA5: Pactado semanas cerradas
A6: 01 | B6: Obras preliminares | G6: =IF(OR(NOT(AND(ISNUMBER(E6),ISNUMBER(F6))),$J$2=""),"",IF(Reprogramaciones!K$9<E6,0,IF(NETWORKDAYS.INTL(E6,F6,11)=0,IF(Reprogramaciones!K$9>=F6,100,0),ROUND(NETWORKDAYS.INTL(E6,MIN(F6,Reprogramaciones!K$9),11)/NETWORKDAYS.INTL(E6,F6,11)*100,1)))-0) | H6: =IF(OR(NOT(AND(ISNUMBER(E6),ISNUMBER(F6))),$J$2=""),"",IF(Reprogramaciones!L$9<E6,0,IF(NETWORKDAYS.INTL(E6,F6,11)=0,IF(Reprogramaciones!L$9>=F6,100,0),ROUND(NETWORKDAYS.INTL(E6,MIN(F6,Reprogramaciones!L$9),11)/NETWORKDAYS.INTL(E6,F6,11)*100,1)))-IF(Reprogramaciones!K$9<E6,0,IF(NETWORKDAYS.INTL(E6,F6,11)=0,IF(Reprogramaciones!K$9>=F6,100,0),ROUND(NETWORKDAYS.INTL(E6,MIN(F6,Reprogramaciones!K$9),11)/NETWORKDAYS.INTL(E6,F6,11)*100,1)))) | I6: =IF(OR(NOT(AND(ISNUMBER(E6),ISNUMBER(F6))),$J$2=""),"",IF(Reprogramaciones!M$9<E6,0,IF(NETWORKDAYS.INTL(E6,F6,11)=0,IF(Reprogramaciones!M$9>=F6,100,0),ROUND(NETWORKDAYS.INTL(E6,MIN(F6,Reprogramaciones!M$9),11)/NETWORKDAYS.INTL(E6,F6,11)*100,1)))-IF(Reprogramaciones!L$9<E6,0,IF(NETWORKDAYS.INTL(E6,F6,11)=0,IF(Reprogramaciones!L$9>=F6,100,0),ROUND(NETWORKDAYS.INTL(E6,MIN(F6,Reprogramaciones!L$9),11)/NETWORKDAYS.INTL(E6,F6,11)*100,1)))) | J6: =IF(OR(NOT(AND(ISNUMBER(E6),ISNUMBER(F6))),$J$2=""),"",IF(Reprogramaciones!N$9<E6,0,IF(NETWORKDAYS.INTL(E6,F6,11)=0,IF(Reprogramaciones!N$9>=F6,100,0),ROUND(NETWORKDAYS.INTL(E6,MIN(F6,Reprogramaciones!N$9),11)/NETWORKDAYS.INTL(E6,F6,11)*100,1)))-IF(Reprogramaciones!M$9<E6,0,IF(NETWORKDAYS.INTL(E6,F6,11)=0,IF(Reprogramaciones!M$9>=F6,100,0),ROUND(NETWORKDAYS.INTL(E6,MIN(F6,Reprogramaciones!M$9),11)/NETWORKDAYS.INTL(E6,F6,11)*100,1)))) | K6: =IF(OR(NOT(AND(ISNUMBER(E6),ISNUMBER(F6))),$J$2=""),"",IF(Reprogramaciones!O$9<E6,0,IF(NETWORKDAYS.INTL(E6,F6,11)=0,IF(Reprogramaciones!O$9>=F6,100,0),ROUND(NETWORKDAYS.INTL(E6,MIN(F6,Reprogramaciones!O$9),11)/NETWORKDAYS.INTL(E6,F6,11)*100,1)))-IF(Reprogramaciones!N$9<E6,0,IF(NETWORKDAYS.INTL(E6,F6,11)=0,IF(Reprogramaciones!N$9>=F6,100,0),ROUND(NETWORKDAYS.INTL(E6,MIN(F6,Reprogramaciones!N$9),11)/NETWORKDAYS.INTL(E6,F6,11)*100,1)))) | L6: =IF(OR(NOT(AND(ISNUMBER(E6),ISNUMBER(F6))),$J$2=""),"",IF(Reprogramaciones!P$9<E6,0,IF(NETWORKDAYS.INTL(E6,F6,11)=0,IF(Reprogramaciones!P$9>=F6,100,0),ROUND(NETWORKDAYS.INTL(E6,MIN(F6,Reprogramaciones!P$9),11)/NETWORKDAYS.INTL(E6,F6,11)*100,1)))-IF(Reprogramaciones!O$9<E6,0,IF(NETWORKDAYS.INTL(E6,F6,11)=0,IF(Reprogramaciones!O$9>=F6,100,0),ROUND(NETWORKDAYS.INTL(E6,MIN(F6,Reprogramaciones!O$9),11)/NETWORKDAYS.INTL(E6,F6,11)*100,1)))) | M6: =IF(OR(NOT(AND(ISNUMBER(E6),ISNUMBER(F6))),$J$2=""),"",IF(Reprogramaciones!Q$9<E6,0,IF(NETWORKDAYS.INTL(E6,F6,11)=0,IF(Reprogramaciones!Q$9>=F6,100,0),ROUND(NETWORKDAYS.INTL(E6,MIN(F6,Reprogramaciones!Q$9),11)/NETWORKDAYS.INTL(E6,F6,11)*100,1)))-IF(Reprogramaciones!P$9<E6,0,IF(NETWORKDAYS.INTL(E6,F6,11)=0,IF(Reprogramaciones!P$9>=F6,100,0),ROUND(NETWORKDAYS.INTL(E6,MIN(F6,Reprogramaciones!P$9),11)/NETWORKDAYS.INTL(E6,F6,11)*100,1)))) | N6: =IF(OR(NOT(AND(ISNUMBER(E6),ISNUMBER(F6))),$J$2=""),"",IF(Reprogramaciones!R$9<E6,0,IF(NETWORKDAYS.INTL(E6,F6,11)=0,IF(Reprogramaciones!R$9>=F6,100,0),ROUND(NETWORKDAYS.INTL(E6,MIN(F6,Reprogramaciones!R$9),11)/NETWORKDAYS.INTL(E6,F6,11)*100,1)))-IF(Reprogramaciones!Q$9<E6,0,IF(NETWORKDAYS.INTL(E6,F6,11)=0,IF(Reprogramaciones!Q$9>=F6,100,0),ROUND(NETWORKDAYS.INTL(E6,MIN(F6,Reprogramaciones!Q$9),11)/NETWORKDAYS.INTL(E6,F6,11)*100,1)))) | O6: =IF(OR(NOT(AND(ISNUMBER(E6),ISNUMBER(F6))),$J$2=""),"",IF(Reprogramaciones!S$9<E6,0,IF(NETWORKDAYS.INTL(E6,F6,11)=0,IF(Reprogramaciones!S$9>=F6,100,0),ROUND(NETWORKDAYS.INTL(E6,MIN(F6,Reprogramaciones!S$9),11)/NETWORKDAYS.INTL(E6,F6,11)*100,1)))-IF(Reprogramaciones!R$9<E6,0,IF(NETWORKDAYS.INTL(E6,F6,11)=0,IF(Reprogramaciones!R$9>=F6,100,0),ROUND(NETWORKDAYS.INTL(E6,MIN(F6,Reprogramaciones!R$9),11)/NETWORKDAYS.INTL(E6,F6,11)*100,1)))) | P6: =IF(OR(NOT(AND(ISNUMBER(E6),ISNUMBER(F6))),$J$2=""),"",IF(Reprogramaciones!T$9<E6,0,IF(NETWORKDAYS.INTL(E6,F6,11)=0,IF(Reprogramaciones!T$9>=F6,100,0),ROUND(NETWORKDAYS.INTL(E6,MIN(F6,Reprogramaciones!T$9),11)/NETWORKDAYS.INTL(E6,F6,11)*100,1)))-IF(Reprogramaciones!S$9<E6,0,IF(NETWORKDAYS.INTL(E6,F6,11)=0,IF(Reprogramaciones!S$9>=F6,100,0),ROUND(NETWORKDAYS.INTL(E6,MIN(F6,Reprogramaciones!S$9),11)/NETWORKDAYS.INTL(E6,F6,11)*100,1)))) | AG6: =IF(AND(ISNUMBER(E6),ISNUMBER(F6)),NETWORKDAYS.INTL(E6,F6,11),"") | AH6: =IF(OR(NOT(AND(ISNUMBER(E6),ISNUMBER(F6))),$J$2=""),"",IF(Reprogramaciones!$P$15<Reprogramaciones!$T$15,0,IF(Reprogramaciones!$R$15>10,MIN(100,SUM($G6:$P6)),MIN(100,SUMPRODUCT((COLUMN($G6:$P6)-COLUMN($G6)+1<Reprogramaciones!$R$15)*$G6:$P6)+N(INDEX($G6:$P6,1,Reprogramaciones!$R$15))*IF(Reprogramaciones!$P$15>=(Reprogramaciones!$T$15+7*(Reprogramaciones!$R$15-1))+6,1,IF(MAX(0,NETWORKDAYS.INTL(MAX(E6,(Reprogramaciones!$T$15+7*(Reprogramaciones!$R$15-1))),MIN(F6,(Reprogramaciones!$T$15+7*(Reprogramaciones!$R$15-1))+6),11))=0,0,MAX(0,NETWORKDAYS.INTL(MAX(E6,(Reprogramaciones!$T$15+7*(Reprogramaciones!$R$15-1))),MIN(F6,Reprogramaciones!$P$15),11))/MAX(0,NETWORKDAYS.INTL(MAX(E6,(Reprogramaciones!$T$15+7*(Reprogramaciones!$R$15-1))),MIN(F6,(Reprogramaciones!$T$15+7*(Reprogramaciones!$R$15-1))+6),11)))))))) | AI6: =IF(COUNT($Q6:$AF6)=0,"",IF(ROUND(SUM($Q6:$AF6),1)>=99.5,100,MIN(100,ROUND(SUM($Q6:$AF6),1)))) | AJ6: =IF(OR(AH6="",AI6=""),"",AI6-AH6) | AK6: =IF(AH6="","",IF(OR(Ficha!$C$10="Suspendida",Ficha!$C$10="Cancelada"),Ficha!$C$10,IF(AND(AI6<>"",N(AI6)>=100),"Completada",IF(AND(E6>TODAY(),N(AI6)=0),"Por iniciar",IF(N(AI6)+0.5<AH6,"Retrasada",IF(N(AI6)+0.5<DA6,IF(Reprogramaciones!$K$15>0,"Al día · Sem "&Reprogramaciones!$K$15&" en curso","Al día · en curso"),"A tiempo")))))) | AL6: =IF(AND(A6="",AND(B6="",C6="",E6="",F6="",COUNT(Q6:AF6)=0)),"",IF(AND(B6="",C6="",E6="",F6="",COUNT(Q6:AF6)=0),"Falta la partida o subpartida",IF(AND(A6<>"",COUNTIF($A$6:$A$305,A6)>1),"Ítem repetido",IF(AND(C6="",E6="",F6="",COUNT(Q6:AF6)=0),"Título de partida",IF(OR(E6="",F6=""),"Faltan fechas",IF(OR(ISTEXT(E6),ISTEXT(F6)),"Fecha escrita como texto: usa dd/mm/aaaa",IF(F6<E6,"Fin antes del inicio",IF(IF($J$2="",FALSE(),OR(E6<$J$2,F6>Reprogramaciones!$T$15+69)),"Fuera de las 10 semanas",IF(ABS(SUM(G6:P6)-100)>0.5,"La meta no suma 100%",IF(ROUND(SUM(Q6:AF6),1)>100.5,"El avance pasa de 100%",IF(MIN(Q6:AF6)<0,"Avance negativo",IF(COUNTA(Q6:AF6)>COUNT(Q6:AF6),"Avance escrito como texto",IF(SUMPRODUCT((Q6:AF6>0)*(Q6:AF6<1))>0,"Avance menor a 1: escribe 50, no 50%",IF(SUMPRODUCT(ISNUMBER(Q6:AF6)*(Reprogramaciones!$K$8:$Z$8>TODAY()))>0,"Avance en semana que aún no llega",IF(AND(N(Reprogramaciones!$E$21)>0,F6>Reprogramaciones!$E$21),"Pasa el fin de la obra: registra una reprogramación",IF(AND(N(Reprogramaciones!$E$21)>0,SUMPRODUCT(ISNUMBER(Q6:AF6)*(Reprogramaciones!$K$8:$Z$8>Reprogramaciones!$E$21))>0),"Avance después del fin de la obra: registra una reprogramación por atraso","OK")))))))))))))))) -> Título de partida | AM6: =IF(OR(OR(NOT(AND(ISNUMBER(E6),ISNUMBER(F6))),$J$2=""),1>MAX(1,Reprogramaciones!$U$15)),"",IF(Reprogramaciones!K$12>=7,"",IF(OR(BT6-N(0)>0.05,N(Q6)>0),ROUNDDOWN(ROUND(BT6,6),0)&"%"&IF(CJ6="",""," / "&CJ6&"%"),IF(AND(N(0)>=99.95,CJ6<>"",N(CJ6)<100),"Pend. "&CJ6&"%","")))) | AN6: =IF(OR(OR(NOT(AND(ISNUMBER(E6),ISNUMBER(F6))),$J$2=""),2>MAX(1,Reprogramaciones!$U$15)),"",IF(Reprogramaciones!L$12>=7,"",IF(OR(BU6-N(BT6)>0.05,N(R6)>0),ROUNDDOWN(ROUND(BU6,6),0)&"%"&IF(CK6="",""," / "&CK6&"%"),IF(AND(N(BT6)>=99.95,CK6<>"",N(CK6)<100),"Pend. "&CK6&"%","")))) | AO6: =IF(OR(OR(NOT(AND(ISNUMBER(E6),ISNUMBER(F6))),$J$2=""),3>MAX(1,Reprogramaciones!$U$15)),"",IF(Reprogramaciones!M$12>=7,"",IF(OR(BV6-N(BU6)>0.05,N(S6)>0),ROUNDDOWN(ROUND(BV6,6),0)&"%"&IF(CL6="",""," / "&CL6&"%"),IF(AND(N(BU6)>=99.95,CL6<>"",N(CL6)<100),"Pend. "&CL6&"%","")))) | AP6: =IF(OR(OR(NOT(AND(ISNUMBER(E6),ISNUMBER(F6))),$J$2=""),4>MAX(1,Reprogramaciones!$U$15)),"",IF(Reprogramaciones!N$12>=7,"",IF(OR(BW6-N(BV6)>0.05,N(T6)>0),ROUNDDOWN(ROUND(BW6,6),0)&"%"&IF(CM6="",""," / "&CM6&"%"),IF(AND(N(BV6)>=99.95,CM6<>"",N(CM6)<100),"Pend. "&CM6&"%","")))) | AQ6: =IF(OR(OR(NOT(AND(ISNUMBER(E6),ISNUMBER(F6))),$J$2=""),5>MAX(1,Reprogramaciones!$U$15)),"",IF(Reprogramaciones!O$12>=7,"",IF(OR(BX6-N(BW6)>0.05,N(U6)>0),ROUNDDOWN(ROUND(BX6,6),0)&"%"&IF(CN6="",""," / "&CN6&"%"),IF(AND(N(BW6)>=99.95,CN6<>"",N(CN6)<100),"Pend. "&CN6&"%","")))) | AR6: =IF(OR(OR(NOT(AND(ISNUMBER(E6),ISNUMBER(F6))),$J$2=""),6>MAX(1,Reprogramaciones!$U$15)),"",IF(Reprogramaciones!P$12>=7,"",IF(OR(BY6-N(BX6)>0.05,N(V6)>0),ROUNDDOWN(ROUND(BY6,6),0)&"%"&IF(CO6="",""," / "&CO6&"%"),IF(AND(N(BX6)>=99.95,CO6<>"",N(CO6)<100),"Pend. "&CO6&"%","")))) | AS6: =IF(OR(OR(NOT(AND(ISNUMBER(E6),ISNUMBER(F6))),$J$2=""),7>MAX(1,Reprogramaciones!$U$15)),"",IF(Reprogramaciones!Q$12>=7,"",IF(OR(BZ6-N(BY6)>0.05,N(W6)>0),ROUNDDOWN(ROUND(BZ6,6),0)&"%"&IF(CP6="",""," / "&CP6&"%"),IF(AND(N(BY6)>=99.95,CP6<>"",N(CP6)<100),"Pend. "&CP6&"%","")))) | AT6: =IF(OR(OR(NOT(AND(ISNUMBER(E6),ISNUMBER(F6))),$J$2=""),8>MAX(1,Reprogramaciones!$U$15)),"",IF(Reprogramaciones!R$12>=7,"",IF(OR(CA6-N(BZ6)>0.05,N(X6)>0),ROUNDDOWN(ROUND(CA6,6),0)&"%"&IF(CQ6="",""," / "&CQ6&"%"),IF(AND(N(BZ6)>=99.95,CQ6<>"",N(CQ6)<100),"Pend. "&CQ6&"%","")))) | AU6: =IF(OR(OR(NOT(AND(ISNUMBER(E6),ISNUMBER(F6))),$J$2=""),9>MAX(1,Reprogramaciones!$U$15)),"",IF(Reprogramaciones!S$12>=7,"",IF(OR(CB6-N(CA6)>0.05,N(Y6)>0),ROUNDDOWN(ROUND(CB6,6),0)&"%"&IF(CR6="",""," / "&CR6&"%"),IF(AND(N(CA6)>=99.95,CR6<>"",N(CR6)<100),"Pend. "&CR6&"%","")))) | AV6: =IF(OR(OR(NOT(AND(ISNUMBER(E6),ISNUMBER(F6))),$J$2=""),10>MAX(1,Reprogramaciones!$U$15)),"",IF(Reprogramaciones!T$12>=7,"",IF(OR(CC6-N(CB6)>0.05,N(Z6)>0),ROUNDDOWN(ROUND(CC6,6),0)&"%"&IF(CS6="",""," / "&CS6&"%"),IF(AND(N(CB6)>=99.95,CS6<>"",N(CS6)<100),"Pend. "&CS6&"%","")))) | AW6: =IF(OR(OR(NOT(AND(ISNUMBER(E6),ISNUMBER(F6))),$J$2=""),11>MAX(1,Reprogramaciones!$U$15)),"",IF(Reprogramaciones!U$12>=7,"",IF(OR(CD6-N(CC6)>0.05,N(AA6)>0),ROUNDDOWN(ROUND(CD6,6),0)&"%"&IF(CT6="",""," / "&CT6&"%"),IF(AND(N(CC6)>=99.95,CT6<>"",N(CT6)<100),"Pend. "&CT6&"%","")))) | AX6: =IF(OR(OR(NOT(AND(ISNUMBER(E6),ISNUMBER(F6))),$J$2=""),12>MAX(1,Reprogramaciones!$U$15)),"",IF(Reprogramaciones!V$12>=7,"",IF(OR(CE6-N(CD6)>0.05,N(AB6)>0),ROUNDDOWN(ROUND(CE6,6),0)&"%"&IF(CU6="",""," / "&CU6&"%"),IF(AND(N(CD6)>=99.95,CU6<>"",N(CU6)<100),"Pend. "&CU6&"%","")))) | AY6: =IF(OR(OR(NOT(AND(ISNUMBER(E6),ISNUMBER(F6))),$J$2=""),13>MAX(1,Reprogramaciones!$U$15)),"",IF(Reprogramaciones!W$12>=7,"",IF(OR(CF6-N(CE6)>0.05,N(AC6)>0),ROUNDDOWN(ROUND(CF6,6),0)&"%"&IF(CV6="",""," / "&CV6&"%"),IF(AND(N(CE6)>=99.95,CV6<>"",N(CV6)<100),"Pend. "&CV6&"%","")))) | AZ6: =IF(OR(OR(NOT(AND(ISNUMBER(E6),ISNUMBER(F6))),$J$2=""),14>MAX(1,Reprogramaciones!$U$15)),"",IF(Reprogramaciones!X$12>=7,"",IF(OR(CG6-N(CF6)>0.05,N(AD6)>0),ROUNDDOWN(ROUND(CG6,6),0)&"%"&IF(CW6="",""," / "&CW6&"%"),IF(AND(N(CF6)>=99.95,CW6<>"",N(CW6)<100),"Pend. "&CW6&"%","")))) | BA6: =IF(OR(OR(NOT(AND(ISNUMBER(E6),ISNUMBER(F6))),$J$2=""),15>MAX(1,Reprogramaciones!$U$15)),"",IF(Reprogramaciones!Y$12>=7,"",IF(OR(CH6-N(CG6)>0.05,N(AE6)>0),ROUNDDOWN(ROUND(CH6,6),0)&"%"&IF(CX6="",""," / "&CX6&"%"),IF(AND(N(CG6)>=99.95,CX6<>"",N(CX6)<100),"Pend. "&CX6&"%","")))) | BB6: =IF(OR(OR(NOT(AND(ISNUMBER(E6),ISNUMBER(F6))),$J$2=""),16>MAX(1,Reprogramaciones!$U$15)),"",IF(Reprogramaciones!Z$12>=7,"",IF(OR(CI6-N(CH6)>0.05,N(AF6)>0),ROUNDDOWN(ROUND(CI6,6),0)&"%"&IF(CY6="",""," / "&CY6&"%"),IF(AND(N(CH6)>=99.95,CY6<>"",N(CY6)<100),"Pend. "&CY6&"%","")))) | BC6: =IF(AND(ISNUMBER(E6),ISNUMBER(F6)),MAX(1,NETWORKDAYS.INTL(E6,F6,11)),0) -> 0 | BD6: =IF(OR(NOT(AND(ISNUMBER(E6),ISNUMBER(F6))),$J$2=""),"",MIN(100,ROUND(SUM($G6:G6),1))) | BE6: =IF(OR(NOT(AND(ISNUMBER(E6),ISNUMBER(F6))),$J$2=""),"",MIN(100,ROUND(SUM($G6:H6),1))) | BF6: =IF(OR(NOT(AND(ISNUMBER(E6),ISNUMBER(F6))),$J$2=""),"",MIN(100,ROUND(SUM($G6:I6),1))) | BG6: =IF(OR(NOT(AND(ISNUMBER(E6),ISNUMBER(F6))),$J$2=""),"",MIN(100,ROUND(SUM($G6:J6),1))) | BH6: =IF(OR(NOT(AND(ISNUMBER(E6),ISNUMBER(F6))),$J$2=""),"",MIN(100,ROUND(SUM($G6:K6),1))) | BI6: =IF(OR(NOT(AND(ISNUMBER(E6),ISNUMBER(F6))),$J$2=""),"",MIN(100,ROUND(SUM($G6:L6),1))) | BJ6: =IF(OR(NOT(AND(ISNUMBER(E6),ISNUMBER(F6))),$J$2=""),"",MIN(100,ROUND(SUM($G6:M6),1))) | BK6: =IF(OR(NOT(AND(ISNUMBER(E6),ISNUMBER(F6))),$J$2=""),"",MIN(100,ROUND(SUM($G6:N6),1))) | BL6: =IF(OR(NOT(AND(ISNUMBER(E6),ISNUMBER(F6))),$J$2=""),"",MIN(100,ROUND(SUM($G6:O6),1))) | BM6: =IF(OR(NOT(AND(ISNUMBER(E6),ISNUMBER(F6))),$J$2=""),"",MIN(100,ROUND(SUM($G6:P6),1))) | BN6: =IF(OR(NOT(AND(ISNUMBER(E6),ISNUMBER(F6))),$J$2=""),"",MIN(100,ROUND(SUM($G6:P6),1))) | BO6: =IF(OR(NOT(AND(ISNUMBER(E6),ISNUMBER(F6))),$J$2=""),"",MIN(100,ROUND(SUM($G6:P6),1))) | BP6: =IF(OR(NOT(AND(ISNUMBER(E6),ISNUMBER(F6))),$J$2=""),"",MIN(100,ROUND(SUM($G6:P6),1))) | BQ6: =IF(OR(NOT(AND(ISNUMBER(E6),ISNUMBER(F6))),$J$2=""),"",MIN(100,ROUND(SUM($G6:P6),1))) | BR6: =IF(OR(NOT(AND(ISNUMBER(E6),ISNUMBER(F6))),$J$2=""),"",MIN(100,ROUND(SUM($G6:P6),1))) | BS6: =IF(OR(NOT(AND(ISNUMBER(E6),ISNUMBER(F6))),$J$2=""),"",MIN(100,ROUND(SUM($G6:P6),1))) | BT6: =IF(OR(NOT(AND(ISNUMBER(E6),ISNUMBER(F6))),$J$2=""),"",IF(Reprogramaciones!K$13<Reprogramaciones!$T$15,0,IF(Reprogramaciones!K$14>10,MIN(100,SUM($G6:$P6)),MIN(100,SUMPRODUCT((COLUMN($G6:$P6)-COLUMN($G6)+1<Reprogramaciones!K$14)*$G6:$P6)+N(INDEX($G6:$P6,1,Reprogramaciones!K$14))*IF(Reprogramaciones!K$13>=(Reprogramaciones!$T$15+7*(Reprogramaciones!K$14-1))+6,1,IF(MAX(0,NETWORKDAYS.INTL(MAX(E6,(Reprogramaciones!$T$15+7*(Reprogramaciones!K$14-1))),MIN(F6,(Reprogramaciones!$T$15+7*(Reprogramaciones!K$14-1))+6),11))=0,0,MAX(0,NETWORKDAYS.INTL(MAX(E6,(Reprogramaciones!$T$15+7*(Reprogramaciones!K$14-1))),MIN(F6,Reprogramaciones!K$13),11))/MAX(0,NETWORKDAYS.INTL(MAX(E6,(Reprogramaciones!$T$15+7*(Reprogramaciones!K$14-1))),MIN(F6,(Reprogramaciones!$T$15+7*(Reprogramaciones!K$14-1))+6),11)))))))) | BU6: =IF(OR(NOT(AND(ISNUMBER(E6),ISNUMBER(F6))),$J$2=""),"",IF(Reprogramaciones!L$13<Reprogramaciones!$T$15,0,IF(Reprogramaciones!L$14>10,MIN(100,SUM($G6:$P6)),MIN(100,SUMPRODUCT((COLUMN($G6:$P6)-COLUMN($G6)+1<Reprogramaciones!L$14)*$G6:$P6)+N(INDEX($G6:$P6,1,Reprogramaciones!L$14))*IF(Reprogramaciones!L$13>=(Reprogramaciones!$T$15+7*(Reprogramaciones!L$14-1))+6,1,IF(MAX(0,NETWORKDAYS.INTL(MAX(E6,(Reprogramaciones!$T$15+7*(Reprogramaciones!L$14-1))),MIN(F6,(Reprogramaciones!$T$15+7*(Reprogramaciones!L$14-1))+6),11))=0,0,MAX(0,NETWORKDAYS.INTL(MAX(E6,(Reprogramaciones!$T$15+7*(Reprogramaciones!L$14-1))),MIN(F6,Reprogramaciones!L$13),11))/MAX(0,NETWORKDAYS.INTL(MAX(E6,(Reprogramaciones!$T$15+7*(Reprogramaciones!L$14-1))),MIN(F6,(Reprogramaciones!$T$15+7*(Reprogramaciones!L$14-1))+6),11)))))))) | BV6: =IF(OR(NOT(AND(ISNUMBER(E6),ISNUMBER(F6))),$J$2=""),"",IF(Reprogramaciones!M$13<Reprogramaciones!$T$15,0,IF(Reprogramaciones!M$14>10,MIN(100,SUM($G6:$P6)),MIN(100,SUMPRODUCT((COLUMN($G6:$P6)-COLUMN($G6)+1<Reprogramaciones!M$14)*$G6:$P6)+N(INDEX($G6:$P6,1,Reprogramaciones!M$14))*IF(Reprogramaciones!M$13>=(Reprogramaciones!$T$15+7*(Reprogramaciones!M$14-1))+6,1,IF(MAX(0,NETWORKDAYS.INTL(MAX(E6,(Reprogramaciones!$T$15+7*(Reprogramaciones!M$14-1))),MIN(F6,(Reprogramaciones!$T$15+7*(Reprogramaciones!M$14-1))+6),11))=0,0,MAX(0,NETWORKDAYS.INTL(MAX(E6,(Reprogramaciones!$T$15+7*(Reprogramaciones!M$14-1))),MIN(F6,Reprogramaciones!M$13),11))/MAX(0,NETWORKDAYS.INTL(MAX(E6,(Reprogramaciones!$T$15+7*(Reprogramaciones!M$14-1))),MIN(F6,(Reprogramaciones!$T$15+7*(Reprogramaciones!M$14-1))+6),11)))))))) | BW6: =IF(OR(NOT(AND(ISNUMBER(E6),ISNUMBER(F6))),$J$2=""),"",IF(Reprogramaciones!N$13<Reprogramaciones!$T$15,0,IF(Reprogramaciones!N$14>10,MIN(100,SUM($G6:$P6)),MIN(100,SUMPRODUCT((COLUMN($G6:$P6)-COLUMN($G6)+1<Reprogramaciones!N$14)*$G6:$P6)+N(INDEX($G6:$P6,1,Reprogramaciones!N$14))*IF(Reprogramaciones!N$13>=(Reprogramaciones!$T$15+7*(Reprogramaciones!N$14-1))+6,1,IF(MAX(0,NETWORKDAYS.INTL(MAX(E6,(Reprogramaciones!$T$15+7*(Reprogramaciones!N$14-1))),MIN(F6,(Reprogramaciones!$T$15+7*(Reprogramaciones!N$14-1))+6),11))=0,0,MAX(0,NETWORKDAYS.INTL(MAX(E6,(Reprogramaciones!$T$15+7*(Reprogramaciones!N$14-1))),MIN(F6,Reprogramaciones!N$13),11))/MAX(0,NETWORKDAYS.INTL(MAX(E6,(Reprogramaciones!$T$15+7*(Reprogramaciones!N$14-1))),MIN(F6,(Reprogramaciones!$T$15+7*(Reprogramaciones!N$14-1))+6),11)))))))) | BX6: =IF(OR(NOT(AND(ISNUMBER(E6),ISNUMBER(F6))),$J$2=""),"",IF(Reprogramaciones!O$13<Reprogramaciones!$T$15,0,IF(Reprogramaciones!O$14>10,MIN(100,SUM($G6:$P6)),MIN(100,SUMPRODUCT((COLUMN($G6:$P6)-COLUMN($G6)+1<Reprogramaciones!O$14)*$G6:$P6)+N(INDEX($G6:$P6,1,Reprogramaciones!O$14))*IF(Reprogramaciones!O$13>=(Reprogramaciones!$T$15+7*(Reprogramaciones!O$14-1))+6,1,IF(MAX(0,NETWORKDAYS.INTL(MAX(E6,(Reprogramaciones!$T$15+7*(Reprogramaciones!O$14-1))),MIN(F6,(Reprogramaciones!$T$15+7*(Reprogramaciones!O$14-1))+6),11))=0,0,MAX(0,NETWORKDAYS.INTL(MAX(E6,(Reprogramaciones!$T$15+7*(Reprogramaciones!O$14-1))),MIN(F6,Reprogramaciones!O$13),11))/MAX(0,NETWORKDAYS.INTL(MAX(E6,(Reprogramaciones!$T$15+7*(Reprogramaciones!O$14-1))),MIN(F6,(Reprogramaciones!$T$15+7*(Reprogramaciones!O$14-1))+6),11)))))))) | BY6: =IF(OR(NOT(AND(ISNUMBER(E6),ISNUMBER(F6))),$J$2=""),"",IF(Reprogramaciones!P$13<Reprogramaciones!$T$15,0,IF(Reprogramaciones!P$14>10,MIN(100,SUM($G6:$P6)),MIN(100,SUMPRODUCT((COLUMN($G6:$P6)-COLUMN($G6)+1<Reprogramaciones!P$14)*$G6:$P6)+N(INDEX($G6:$P6,1,Reprogramaciones!P$14))*IF(Reprogramaciones!P$13>=(Reprogramaciones!$T$15+7*(Reprogramaciones!P$14-1))+6,1,IF(MAX(0,NETWORKDAYS.INTL(MAX(E6,(Reprogramaciones!$T$15+7*(Reprogramaciones!P$14-1))),MIN(F6,(Reprogramaciones!$T$15+7*(Reprogramaciones!P$14-1))+6),11))=0,0,MAX(0,NETWORKDAYS.INTL(MAX(E6,(Reprogramaciones!$T$15+7*(Reprogramaciones!P$14-1))),MIN(F6,Reprogramaciones!P$13),11))/MAX(0,NETWORKDAYS.INTL(MAX(E6,(Reprogramaciones!$T$15+7*(Reprogramaciones!P$14-1))),MIN(F6,(Reprogramaciones!$T$15+7*(Reprogramaciones!P$14-1))+6),11)))))))) | BZ6: =IF(OR(NOT(AND(ISNUMBER(E6),ISNUMBER(F6))),$J$2=""),"",IF(Reprogramaciones!Q$13<Reprogramaciones!$T$15,0,IF(Reprogramaciones!Q$14>10,MIN(100,SUM($G6:$P6)),MIN(100,SUMPRODUCT((COLUMN($G6:$P6)-COLUMN($G6)+1<Reprogramaciones!Q$14)*$G6:$P6)+N(INDEX($G6:$P6,1,Reprogramaciones!Q$14))*IF(Reprogramaciones!Q$13>=(Reprogramaciones!$T$15+7*(Reprogramaciones!Q$14-1))+6,1,IF(MAX(0,NETWORKDAYS.INTL(MAX(E6,(Reprogramaciones!$T$15+7*(Reprogramaciones!Q$14-1))),MIN(F6,(Reprogramaciones!$T$15+7*(Reprogramaciones!Q$14-1))+6),11))=0,0,MAX(0,NETWORKDAYS.INTL(MAX(E6,(Reprogramaciones!$T$15+7*(Reprogramaciones!Q$14-1))),MIN(F6,Reprogramaciones!Q$13),11))/MAX(0,NETWORKDAYS.INTL(MAX(E6,(Reprogramaciones!$T$15+7*(Reprogramaciones!Q$14-1))),MIN(F6,(Reprogramaciones!$T$15+7*(Reprogramaciones!Q$14-1))+6),11)))))))) | CA6: =IF(OR(NOT(AND(ISNUMBER(E6),ISNUMBER(F6))),$J$2=""),"",IF(Reprogramaciones!R$13<Reprogramaciones!$T$15,0,IF(Reprogramaciones!R$14>10,MIN(100,SUM($G6:$P6)),MIN(100,SUMPRODUCT((COLUMN($G6:$P6)-COLUMN($G6)+1<Reprogramaciones!R$14)*$G6:$P6)+N(INDEX($G6:$P6,1,Reprogramaciones!R$14))*IF(Reprogramaciones!R$13>=(Reprogramaciones!$T$15+7*(Reprogramaciones!R$14-1))+6,1,IF(MAX(0,NETWORKDAYS.INTL(MAX(E6,(Reprogramaciones!$T$15+7*(Reprogramaciones!R$14-1))),MIN(F6,(Reprogramaciones!$T$15+7*(Reprogramaciones!R$14-1))+6),11))=0,0,MAX(0,NETWORKDAYS.INTL(MAX(E6,(Reprogramaciones!$T$15+7*(Reprogramaciones!R$14-1))),MIN(F6,Reprogramaciones!R$13),11))/MAX(0,NETWORKDAYS.INTL(MAX(E6,(Reprogramaciones!$T$15+7*(Reprogramaciones!R$14-1))),MIN(F6,(Reprogramaciones!$T$15+7*(Reprogramaciones!R$14-1))+6),11)))))))) | CB6: =IF(OR(NOT(AND(ISNUMBER(E6),ISNUMBER(F6))),$J$2=""),"",IF(Reprogramaciones!S$13<Reprogramaciones!$T$15,0,IF(Reprogramaciones!S$14>10,MIN(100,SUM($G6:$P6)),MIN(100,SUMPRODUCT((COLUMN($G6:$P6)-COLUMN($G6)+1<Reprogramaciones!S$14)*$G6:$P6)+N(INDEX($G6:$P6,1,Reprogramaciones!S$14))*IF(Reprogramaciones!S$13>=(Reprogramaciones!$T$15+7*(Reprogramaciones!S$14-1))+6,1,IF(MAX(0,NETWORKDAYS.INTL(MAX(E6,(Reprogramaciones!$T$15+7*(Reprogramaciones!S$14-1))),MIN(F6,(Reprogramaciones!$T$15+7*(Reprogramaciones!S$14-1))+6),11))=0,0,MAX(0,NETWORKDAYS.INTL(MAX(E6,(Reprogramaciones!$T$15+7*(Reprogramaciones!S$14-1))),MIN(F6,Reprogramaciones!S$13),11))/MAX(0,NETWORKDAYS.INTL(MAX(E6,(Reprogramaciones!$T$15+7*(Reprogramaciones!S$14-1))),MIN(F6,(Reprogramaciones!$T$15+7*(Reprogramaciones!S$14-1))+6),11)))))))) | CC6: =IF(OR(NOT(AND(ISNUMBER(E6),ISNUMBER(F6))),$J$2=""),"",IF(Reprogramaciones!T$13<Reprogramaciones!$T$15,0,IF(Reprogramaciones!T$14>10,MIN(100,SUM($G6:$P6)),MIN(100,SUMPRODUCT((COLUMN($G6:$P6)-COLUMN($G6)+1<Reprogramaciones!T$14)*$G6:$P6)+N(INDEX($G6:$P6,1,Reprogramaciones!T$14))*IF(Reprogramaciones!T$13>=(Reprogramaciones!$T$15+7*(Reprogramaciones!T$14-1))+6,1,IF(MAX(0,NETWORKDAYS.INTL(MAX(E6,(Reprogramaciones!$T$15+7*(Reprogramaciones!T$14-1))),MIN(F6,(Reprogramaciones!$T$15+7*(Reprogramaciones!T$14-1))+6),11))=0,0,MAX(0,NETWORKDAYS.INTL(MAX(E6,(Reprogramaciones!$T$15+7*(Reprogramaciones!T$14-1))),MIN(F6,Reprogramaciones!T$13),11))/MAX(0,NETWORKDAYS.INTL(MAX(E6,(Reprogramaciones!$T$15+7*(Reprogramaciones!T$14-1))),MIN(F6,(Reprogramaciones!$T$15+7*(Reprogramaciones!T$14-1))+6),11)))))))) | CD6: =IF(OR(NOT(AND(ISNUMBER(E6),ISNUMBER(F6))),$J$2=""),"",IF(Reprogramaciones!U$13<Reprogramaciones!$T$15,0,IF(Reprogramaciones!U$14>10,MIN(100,SUM($G6:$P6)),MIN(100,SUMPRODUCT((COLUMN($G6:$P6)-COLUMN($G6)+1<Reprogramaciones!U$14)*$G6:$P6)+N(INDEX($G6:$P6,1,Reprogramaciones!U$14))*IF(Reprogramaciones!U$13>=(Reprogramaciones!$T$15+7*(Reprogramaciones!U$14-1))+6,1,IF(MAX(0,NETWORKDAYS.INTL(MAX(E6,(Reprogramaciones!$T$15+7*(Reprogramaciones!U$14-1))),MIN(F6,(Reprogramaciones!$T$15+7*(Reprogramaciones!U$14-1))+6),11))=0,0,MAX(0,NETWORKDAYS.INTL(MAX(E6,(Reprogramaciones!$T$15+7*(Reprogramaciones!U$14-1))),MIN(F6,Reprogramaciones!U$13),11))/MAX(0,NETWORKDAYS.INTL(MAX(E6,(Reprogramaciones!$T$15+7*(Reprogramaciones!U$14-1))),MIN(F6,(Reprogramaciones!$T$15+7*(Reprogramaciones!U$14-1))+6),11)))))))) | CE6: =IF(OR(NOT(AND(ISNUMBER(E6),ISNUMBER(F6))),$J$2=""),"",IF(Reprogramaciones!V$13<Reprogramaciones!$T$15,0,IF(Reprogramaciones!V$14>10,MIN(100,SUM($G6:$P6)),MIN(100,SUMPRODUCT((COLUMN($G6:$P6)-COLUMN($G6)+1<Reprogramaciones!V$14)*$G6:$P6)+N(INDEX($G6:$P6,1,Reprogramaciones!V$14))*IF(Reprogramaciones!V$13>=(Reprogramaciones!$T$15+7*(Reprogramaciones!V$14-1))+6,1,IF(MAX(0,NETWORKDAYS.INTL(MAX(E6,(Reprogramaciones!$T$15+7*(Reprogramaciones!V$14-1))),MIN(F6,(Reprogramaciones!$T$15+7*(Reprogramaciones!V$14-1))+6),11))=0,0,MAX(0,NETWORKDAYS.INTL(MAX(E6,(Reprogramaciones!$T$15+7*(Reprogramaciones!V$14-1))),MIN(F6,Reprogramaciones!V$13),11))/MAX(0,NETWORKDAYS.INTL(MAX(E6,(Reprogramaciones!$T$15+7*(Reprogramaciones!V$14-1))),MIN(F6,(Reprogramaciones!$T$15+7*(Reprogramaciones!V$14-1))+6),11)))))))) | CF6: =IF(OR(NOT(AND(ISNUMBER(E6),ISNUMBER(F6))),$J$2=""),"",IF(Reprogramaciones!W$13<Reprogramaciones!$T$15,0,IF(Reprogramaciones!W$14>10,MIN(100,SUM($G6:$P6)),MIN(100,SUMPRODUCT((COLUMN($G6:$P6)-COLUMN($G6)+1<Reprogramaciones!W$14)*$G6:$P6)+N(INDEX($G6:$P6,1,Reprogramaciones!W$14))*IF(Reprogramaciones!W$13>=(Reprogramaciones!$T$15+7*(Reprogramaciones!W$14-1))+6,1,IF(MAX(0,NETWORKDAYS.INTL(MAX(E6,(Reprogramaciones!$T$15+7*(Reprogramaciones!W$14-1))),MIN(F6,(Reprogramaciones!$T$15+7*(Reprogramaciones!W$14-1))+6),11))=0,0,MAX(0,NETWORKDAYS.INTL(MAX(E6,(Reprogramaciones!$T$15+7*(Reprogramaciones!W$14-1))),MIN(F6,Reprogramaciones!W$13),11))/MAX(0,NETWORKDAYS.INTL(MAX(E6,(Reprogramaciones!$T$15+7*(Reprogramaciones!W$14-1))),MIN(F6,(Reprogramaciones!$T$15+7*(Reprogramaciones!W$14-1))+6),11)))))))) | CG6: =IF(OR(NOT(AND(ISNUMBER(E6),ISNUMBER(F6))),$J$2=""),"",IF(Reprogramaciones!X$13<Reprogramaciones!$T$15,0,IF(Reprogramaciones!X$14>10,MIN(100,SUM($G6:$P6)),MIN(100,SUMPRODUCT((COLUMN($G6:$P6)-COLUMN($G6)+1<Reprogramaciones!X$14)*$G6:$P6)+N(INDEX($G6:$P6,1,Reprogramaciones!X$14))*IF(Reprogramaciones!X$13>=(Reprogramaciones!$T$15+7*(Reprogramaciones!X$14-1))+6,1,IF(MAX(0,NETWORKDAYS.INTL(MAX(E6,(Reprogramaciones!$T$15+7*(Reprogramaciones!X$14-1))),MIN(F6,(Reprogramaciones!$T$15+7*(Reprogramaciones!X$14-1))+6),11))=0,0,MAX(0,NETWORKDAYS.INTL(MAX(E6,(Reprogramaciones!$T$15+7*(Reprogramaciones!X$14-1))),MIN(F6,Reprogramaciones!X$13),11))/MAX(0,NETWORKDAYS.INTL(MAX(E6,(Reprogramaciones!$T$15+7*(Reprogramaciones!X$14-1))),MIN(F6,(Reprogramaciones!$T$15+7*(Reprogramaciones!X$14-1))+6),11)))))))) | CH6: =IF(OR(NOT(AND(ISNUMBER(E6),ISNUMBER(F6))),$J$2=""),"",IF(Reprogramaciones!Y$13<Reprogramaciones!$T$15,0,IF(Reprogramaciones!Y$14>10,MIN(100,SUM($G6:$P6)),MIN(100,SUMPRODUCT((COLUMN($G6:$P6)-COLUMN($G6)+1<Reprogramaciones!Y$14)*$G6:$P6)+N(INDEX($G6:$P6,1,Reprogramaciones!Y$14))*IF(Reprogramaciones!Y$13>=(Reprogramaciones!$T$15+7*(Reprogramaciones!Y$14-1))+6,1,IF(MAX(0,NETWORKDAYS.INTL(MAX(E6,(Reprogramaciones!$T$15+7*(Reprogramaciones!Y$14-1))),MIN(F6,(Reprogramaciones!$T$15+7*(Reprogramaciones!Y$14-1))+6),11))=0,0,MAX(0,NETWORKDAYS.INTL(MAX(E6,(Reprogramaciones!$T$15+7*(Reprogramaciones!Y$14-1))),MIN(F6,Reprogramaciones!Y$13),11))/MAX(0,NETWORKDAYS.INTL(MAX(E6,(Reprogramaciones!$T$15+7*(Reprogramaciones!Y$14-1))),MIN(F6,(Reprogramaciones!$T$15+7*(Reprogramaciones!Y$14-1))+6),11)))))))) | CI6: =IF(OR(NOT(AND(ISNUMBER(E6),ISNUMBER(F6))),$J$2=""),"",IF(Reprogramaciones!Z$13<Reprogramaciones!$T$15,0,IF(Reprogramaciones!Z$14>10,MIN(100,SUM($G6:$P6)),MIN(100,SUMPRODUCT((COLUMN($G6:$P6)-COLUMN($G6)+1<Reprogramaciones!Z$14)*$G6:$P6)+N(INDEX($G6:$P6,1,Reprogramaciones!Z$14))*IF(Reprogramaciones!Z$13>=(Reprogramaciones!$T$15+7*(Reprogramaciones!Z$14-1))+6,1,IF(MAX(0,NETWORKDAYS.INTL(MAX(E6,(Reprogramaciones!$T$15+7*(Reprogramaciones!Z$14-1))),MIN(F6,(Reprogramaciones!$T$15+7*(Reprogramaciones!Z$14-1))+6),11))=0,0,MAX(0,NETWORKDAYS.INTL(MAX(E6,(Reprogramaciones!$T$15+7*(Reprogramaciones!Z$14-1))),MIN(F6,Reprogramaciones!Z$13),11))/MAX(0,NETWORKDAYS.INTL(MAX(E6,(Reprogramaciones!$T$15+7*(Reprogramaciones!Z$14-1))),MIN(F6,(Reprogramaciones!$T$15+7*(Reprogramaciones!Z$14-1))+6),11)))))))) | CJ6: =IF(OR(OR(NOT(AND(ISNUMBER(E6),ISNUMBER(F6))),$J$2=""),1>Reprogramaciones!$K$16),"",IF(ROUND(SUM($Q6:Q6),1)>=99.5,100,MIN(100,ROUND(SUM($Q6:Q6),1)))) | CK6: =IF(OR(OR(NOT(AND(ISNUMBER(E6),ISNUMBER(F6))),$J$2=""),2>Reprogramaciones!$K$16),"",IF(ROUND(SUM($Q6:R6),1)>=99.5,100,MIN(100,ROUND(SUM($Q6:R6),1)))) | CL6: =IF(OR(OR(NOT(AND(ISNUMBER(E6),ISNUMBER(F6))),$J$2=""),3>Reprogramaciones!$K$16),"",IF(ROUND(SUM($Q6:S6),1)>=99.5,100,MIN(100,ROUND(SUM($Q6:S6),1)))) | CM6: =IF(OR(OR(NOT(AND(ISNUMBER(E6),ISNUMBER(F6))),$J$2=""),4>Reprogramaciones!$K$16),"",IF(ROUND(SUM($Q6:T6),1)>=99.5,100,MIN(100,ROUND(SUM($Q6:T6),1)))) | CN6: =IF(OR(OR(NOT(AND(ISNUMBER(E6),ISNUMBER(F6))),$J$2=""),5>Reprogramaciones!$K$16),"",IF(ROUND(SUM($Q6:U6),1)>=99.5,100,MIN(100,ROUND(SUM($Q6:U6),1)))) | CO6: =IF(OR(OR(NOT(AND(ISNUMBER(E6),ISNUMBER(F6))),$J$2=""),6>Reprogramaciones!$K$16),"",IF(ROUND(SUM($Q6:V6),1)>=99.5,100,MIN(100,ROUND(SUM($Q6:V6),1)))) | CP6: =IF(OR(OR(NOT(AND(ISNUMBER(E6),ISNUMBER(F6))),$J$2=""),7>Reprogramaciones!$K$16),"",IF(ROUND(SUM($Q6:W6),1)>=99.5,100,MIN(100,ROUND(SUM($Q6:W6),1)))) | CQ6: =IF(OR(OR(NOT(AND(ISNUMBER(E6),ISNUMBER(F6))),$J$2=""),8>Reprogramaciones!$K$16),"",IF(ROUND(SUM($Q6:X6),1)>=99.5,100,MIN(100,ROUND(SUM($Q6:X6),1)))) | CR6: =IF(OR(OR(NOT(AND(ISNUMBER(E6),ISNUMBER(F6))),$J$2=""),9>Reprogramaciones!$K$16),"",IF(ROUND(SUM($Q6:Y6),1)>=99.5,100,MIN(100,ROUND(SUM($Q6:Y6),1)))) | CS6: =IF(OR(OR(NOT(AND(ISNUMBER(E6),ISNUMBER(F6))),$J$2=""),10>Reprogramaciones!$K$16),"",IF(ROUND(SUM($Q6:Z6),1)>=99.5,100,MIN(100,ROUND(SUM($Q6:Z6),1)))) | CT6: =IF(OR(OR(NOT(AND(ISNUMBER(E6),ISNUMBER(F6))),$J$2=""),11>Reprogramaciones!$K$16),"",IF(ROUND(SUM($Q6:AA6),1)>=99.5,100,MIN(100,ROUND(SUM($Q6:AA6),1)))) | CU6: =IF(OR(OR(NOT(AND(ISNUMBER(E6),ISNUMBER(F6))),$J$2=""),12>Reprogramaciones!$K$16),"",IF(ROUND(SUM($Q6:AB6),1)>=99.5,100,MIN(100,ROUND(SUM($Q6:AB6),1)))) | CV6: =IF(OR(OR(NOT(AND(ISNUMBER(E6),ISNUMBER(F6))),$J$2=""),13>Reprogramaciones!$K$16),"",IF(ROUND(SUM($Q6:AC6),1)>=99.5,100,MIN(100,ROUND(SUM($Q6:AC6),1)))) | CW6: =IF(OR(OR(NOT(AND(ISNUMBER(E6),ISNUMBER(F6))),$J$2=""),14>Reprogramaciones!$K$16),"",IF(ROUND(SUM($Q6:AD6),1)>=99.5,100,MIN(100,ROUND(SUM($Q6:AD6),1)))) | CX6: =IF(OR(OR(NOT(AND(ISNUMBER(E6),ISNUMBER(F6))),$J$2=""),15>Reprogramaciones!$K$16),"",IF(ROUND(SUM($Q6:AE6),1)>=99.5,100,MIN(100,ROUND(SUM($Q6:AE6),1)))) | CY6: =IF(OR(OR(NOT(AND(ISNUMBER(E6),ISNUMBER(F6))),$J$2=""),16>Reprogramaciones!$K$16),"",IF(ROUND(SUM($Q6:AF6),1)>=99.5,100,MIN(100,ROUND(SUM($Q6:AF6),1)))) | CZ6: =IF(D6<>"",D6,IF(B6<>"","Contractual","Contractual")) -> Contractual | DA6: =IF(OR(NOT(AND(ISNUMBER(E6),ISNUMBER(F6))),$J$2=""),"",IF(Reprogramaciones!$Q$15<Reprogramaciones!$T$15,0,IF(Reprogramaciones!$S$15>10,MIN(100,SUM($G6:$P6)),MIN(100,SUMPRODUCT((COLUMN($G6:$P6)-COLUMN($G6)+1<Reprogramaciones!$S$15)*$G6:$P6)+N(INDEX($G6:$P6,1,Reprogramaciones!$S$15))*IF(Reprogramaciones!$Q$15>=(Reprogramaciones!$T$15+7*(Reprogramaciones!$S$15-1))+6,1,IF(MAX(0,NETWORKDAYS.INTL(MAX(E6,(Reprogramaciones!$T$15+7*(Reprogramaciones!$S$15-1))),MIN(F6,(Reprogramaciones!$T$15+7*(Reprogramaciones!$S$15-1))+6),11))=0,0,MAX(0,NETWORKDAYS.INTL(MAX(E6,(Reprogramaciones!$T$15+7*(Reprogramaciones!$S$15-1))),MIN(F6,Reprogramaciones!$Q$15),11))/MAX(0,NETWORKDAYS.INTL(MAX(E6,(Reprogramaciones!$T$15+7*(Reprogramaciones!$S$15-1))),MIN(F6,(Reprogramaciones!$T$15+7*(Reprogramaciones!$S$15-1))+6),11))))))))
